<?xml version="1.0" encoding="utf-8"?>

<robot xmlns:xacro="http://www.ros.org/wiki/xacro" name="humrs">
  <link name="head">
    <visual>
      <origin rpy="0 0 0" xyz="0 0 -0.033788"/>
      <geometry>
        <cylinder length="0.067576" radius="0.0263525"/>
      </geometry>
      <material name="white">
        <color rgba="1 1 1 1"/>
      </material>
    </visual>
    <collision>
      <origin rpy="0 0 0" xyz="0 0 -0.033788"/>
      <geometry>
        <cylinder length="0.067576" radius="0.0263525"/>
      </geometry>
    </collision>
    <inertial>
      <origin rpy="0 0 0" xyz="0 0 -0.033788"/>
      <mass value="0.67"/>
      <inertia ixx="0.000371284885415" ixy="0" ixz="0" iyy="0.000371284885415" iyz="0" izz="0.000232642175844"/>
    </inertial>
  </link>
  <joint name="head__OUTPUT_INTERFACE" type="fixed">
    <parent link="head"/>
    <child link="radial1__INPUT_INTERFACE"/>
    <origin rpy="0 0 1.57079632679" xyz="0 0 -0.067576"/>
  </joint>
  <link name="head__COLLAR">
    <visual>
      <geometry>
        <mesh filename="package://humrs_robot_description/meshes/collar.stl"/>
      </geometry>
      <material name="black">
        <color rgba="0 0 0 1"/>
      </material>
    </visual>
  </link>
  <joint name="head__COLLAR_JOINT" type="fixed">
    <origin rpy="0 -1.57079632679 0" xyz="0 0 -0.067576"/>
    <parent link="head"/>
    <child link="head__COLLAR"/>
  </joint>
  <link name="radial1__INPUT_INTERFACE">
    <visual>
      <origin rpy="-1.57079632679 0 0" xyz="0 0 -0.03003515"/>
      <geometry>
        <mesh filename="package://humrs_robot_description/meshes/radial_thruster_body.stl"/>
      </geometry>
      <material name="blue">
        <color rgba="0 0 1 1"/>
      </material>
    </visual>
    <collision>
      <origin rpy="0 0 0" xyz="0 0 -0.03003515"/>
      <geometry>
        <cylinder length="0.0600703" radius="0.0253925"/>
      </geometry>
    </collision>
    <inertial>
      <origin rpy="0 0 0" xyz="0 0 -0.03003515"/>
      <mass value="0.67"/>
      <inertia ixx="0.000309471777855" ixy="0" ixz="0" iyy="0.000309471777855" iyz="0" izz="0.000216000983844"/>
    </inertial>
  </link>
  <link name="radial1_propeller_h">
    <visual>
      <geometry>
        <mesh filename="package://humrs_robot_description/meshes/radial_propeller_h.stl"/>
      </geometry>
      <material name="black">
        <color rgba="0 0 0 1"/>
      </material>
    </visual>
  </link>
  <joint name="radial1__PROPH_JOINT" type="continuous">
    <parent link="radial1__INPUT_INTERFACE"/>
    <child link="radial1_propeller_h"/>
    <origin rpy="0 1.57079632679 0" xyz="0 0 -0.0432259"/>
    <axis xyz="0 0 1"/>
    <dynamics damping=".1" friction="0.2"/>
    <limit effort="7.0" velocity="20"/>
  </joint>
  <transmission name="radial1__PROPH_JOINT_trans">
    <type>transmission_interface/SimpleTransmission</type>
    <joint name="radial1__PROPH_JOINT">
      <hardwareInterface>PositionJointInterface</hardwareInterface>
    </joint>
    <actuator name="radial1__PROPH_JOINT_motor">
      <hardwareInterface>PositionJointInterface</hardwareInterface>
      <mechanicalReduction>1</mechanicalReduction>
    </actuator>
  </transmission>
  <link name="radial1_propeller_v">
    <visual>
      <geometry>
        <mesh filename="package://humrs_robot_description/meshes/radial_propeller_v.stl"/>
      </geometry>
      <material name="black">
        <color rgba="0 0 0 1"/>
      </material>
    </visual>
  </link>
  <joint name="radial1__PROPV_JOINT" type="continuous">
    <parent link="radial1__INPUT_INTERFACE"/>
    <child link="radial1_propeller_v"/>
    <origin rpy="1.57079632679 0 0" xyz="0 0 -0.022426"/>
    <axis xyz="0 0 1"/>
    <dynamics damping=".1" friction="0.2"/>
    <limit effort="7.0" velocity="20"/>
  </joint>
  <transmission name="radial1__PROPV_JOINT_trans">
    <type>transmission_interface/SimpleTransmission</type>
    <joint name="radial1__PROPV_JOINT">
      <hardwareInterface>PositionJointInterface</hardwareInterface>
    </joint>
    <actuator name="radial1__PROPV_JOINT_motor">
      <hardwareInterface>PositionJointInterface</hardwareInterface>
      <mechanicalReduction>1</mechanicalReduction>
    </actuator>
  </transmission>
  <link name="radial1__COLLAR">
    <visual>
      <geometry>
        <mesh filename="package://humrs_robot_description/meshes/collar.stl"/>
      </geometry>
      <material name="black">
        <color rgba="0 0 0 1"/>
      </material>
    </visual>
  </link>
  <joint name="radial1__COLLAR_JOINT" type="fixed">
    <origin rpy="0 -1.57079632679 0" xyz="0 0 -0.0600703"/>
    <parent link="radial1__INPUT_INTERFACE"/>
    <child link="radial1__COLLAR"/>
  </joint>
  <joint name="radial1__OUTPUT_INTERFACE" type="fixed">
    <parent link="radial1__INPUT_INTERFACE"/>
    <child link="rotary1__INPUT_INTERFACE"/>
    <origin rpy="0 0 -1.57079632679" xyz="0 0 -0.0600703"/>
  </joint>
  <link name="rotary1__INPUT_INTERFACE">
    <visual>
      <origin rpy="0 -1.57079632679 0" xyz="0 0 -0.0187325"/>
      <geometry>
        <mesh filename="package://humrs_robot_description/meshes/rotary_male.stl"/>
      </geometry>
      <material name="red">
        <color rgba=".82 0.06 0.06 1"/>
      </material>
    </visual>
    <collision>
      <origin rpy="0 0 0" xyz="0 0 -0.000379875"/>
      <geometry>
        <cylinder length="0.000379875" radius="0.0254"/>
      </geometry>
    </collision>
    <inertial>
      <origin rpy="0 0 0" xyz="0 0 -0.000379875"/>
      <mass value="0.335"/>
      <inertia ixx="5.40482640601e-05" ixy="0" ixz="0" iyy="5.40482640601e-05" iyz="0" izz="0.0001080643"/>
    </inertial>
  </link>
  <joint name="rotary1__JOINT" type="revolute">
    <parent link="rotary1__INPUT_INTERFACE"/>
    <child link="rotary1__OUTPUT_BODY"/>
    <origin rpy="0 0 0" xyz="0 0 -0.0273"/>
    <axis xyz="1 0 0"/>
    <dynamics damping=".1" friction="0.2"/>
    <limit effort="7.0" lower="-1.57" upper="1.57" velocity="2.208932"/>
  </joint>
  <transmission name="rotary1_trans">
    <type>transmission_interface/SimpleTransmission</type>
    <joint name="rotary1__JOINT">
      <hardwareInterface>PositionJointInterface</hardwareInterface>
    </joint>
    <actuator name="rotary1__JOINT_motor">
      <hardwareInterface>PositionJointInterface</hardwareInterface>
      <mechanicalReduction>300</mechanicalReduction>
    </actuator>
  </transmission>
  <link name="rotary1__OUTPUT_BODY">
    <visual>
      <origin rpy="0 0 0" xyz="0 0 -0.0087453"/>
      <geometry>
        <mesh filename="package://humrs_robot_description/meshes/rotary_female.stl"/>
      </geometry>
      <material name="red">
        <color rgba=".82 0.06 0.06 1"/>
      </material>
    </visual>
    <collision>
      <origin rpy="0 0 0" xyz="0 0 -0.0087453"/>
      <geometry>
        <cylinder length="0.053107" radius="0.0257805"/>
      </geometry>
    </collision>
    <inertial>
      <origin rpy="0 0 0" xyz="0 0 -0.0087453"/>
      <mass value="0.335"/>
      <inertia ixx="0.000134397979714" ixy="0" ixz="0" iyy="0.000134397979714" iyz="0" izz="0.000111326225192"/>
    </inertial>
  </link>
  <joint name="rotary1__OUTPUT_INTERFACE" type="fixed">
    <parent link="rotary1__OUTPUT_BODY"/>
    <child link="rotary2__INPUT_INTERFACE"/>
    <origin rpy="0 0 1.57079632679" xyz="0 0 -0.0352988"/>
  </joint>
  <link name="rotary1__COLLAR">
    <visual>
      <origin rpy="0 1.57079632679 0" xyz="0 0 -0.0352988"/>
      <geometry>
        <mesh filename="package://humrs_robot_description/meshes/collar.stl"/>
      </geometry>
      <material name="black">
        <color rgba="0 0 0 1"/>
      </material>
    </visual>
  </link>
  <joint name="rotary1__COLLAR_JOINT" type="fixed">
    <parent link="rotary1__OUTPUT_BODY"/>
    <child link="rotary1__COLLAR"/>
  </joint>
  <link name="rotary2__INPUT_INTERFACE">
    <visual>
      <origin rpy="0 -1.57079632679 0" xyz="0 0 -0.0187325"/>
      <geometry>
        <mesh filename="package://humrs_robot_description/meshes/rotary_male.stl"/>
      </geometry>
      <material name="red">
        <color rgba=".82 0.06 0.06 1"/>
      </material>
    </visual>
    <collision>
      <origin rpy="0 0 0" xyz="0 0 -0.000379875"/>
      <geometry>
        <cylinder length="0.000379875" radius="0.0254"/>
      </geometry>
    </collision>
    <inertial>
      <origin rpy="0 0 0" xyz="0 0 -0.000379875"/>
      <mass value="0.335"/>
      <inertia ixx="5.40482640601e-05" ixy="0" ixz="0" iyy="5.40482640601e-05" iyz="0" izz="0.0001080643"/>
    </inertial>
  </link>
  <joint name="rotary2__JOINT" type="revolute">
    <parent link="rotary2__INPUT_INTERFACE"/>
    <child link="rotary2__OUTPUT_BODY"/>
    <origin rpy="0 0 0" xyz="0 0 -0.0273"/>
    <axis xyz="1 0 0"/>
    <dynamics damping=".1" friction="0.2"/>
    <limit effort="7.0" lower="-1.57" upper="1.57" velocity="2.208932"/>
  </joint>
  <transmission name="rotary2_trans">
    <type>transmission_interface/SimpleTransmission</type>
    <joint name="rotary2__JOINT">
      <hardwareInterface>PositionJointInterface</hardwareInterface>
    </joint>
    <actuator name="rotary2__JOINT_motor">
      <hardwareInterface>PositionJointInterface</hardwareInterface>
      <mechanicalReduction>300</mechanicalReduction>
    </actuator>
  </transmission>
  <link name="rotary2__OUTPUT_BODY">
    <visual>
      <origin rpy="0 0 0" xyz="0 0 -0.0087453"/>
      <geometry>
        <mesh filename="package://humrs_robot_description/meshes/rotary_female.stl"/>
      </geometry>
      <material name="red">
        <color rgba=".82 0.06 0.06 1"/>
      </material>
    </visual>
    <collision>
      <origin rpy="0 0 0" xyz="0 0 -0.0087453"/>
      <geometry>
        <cylinder length="0.053107" radius="0.0257805"/>
      </geometry>
    </collision>
    <inertial>
      <origin rpy="0 0 0" xyz="0 0 -0.0087453"/>
      <mass value="0.335"/>
      <inertia ixx="0.000134397979714" ixy="0" ixz="0" iyy="0.000134397979714" iyz="0" izz="0.000111326225192"/>
    </inertial>
  </link>
  <joint name="rotary2__OUTPUT_INTERFACE" type="fixed">
    <parent link="rotary2__OUTPUT_BODY"/>
    <child link="axial__INPUT_INTERFACE"/>
    <origin rpy="0 0 0" xyz="0 0 -0.0352988"/>
  </joint>
  <link name="rotary2__COLLAR">
    <visual>
      <origin rpy="0 1.57079632679 0" xyz="0 0 -0.0352988"/>
      <geometry>
        <mesh filename="package://humrs_robot_description/meshes/collar.stl"/>
      </geometry>
      <material name="black">
        <color rgba="0 0 0 1"/>
      </material>
    </visual>
  </link>
  <joint name="rotary2__COLLAR_JOINT" type="fixed">
    <parent link="rotary2__OUTPUT_BODY"/>
    <child link="rotary2__COLLAR"/>
  </joint>
  <link name="axial__INPUT_INTERFACE">
    <visual>
      <origin rpy="-1.57079632679 0 0" xyz="0 0 -0.05775515"/>
      <geometry>
        <mesh filename="package://humrs_robot_description/meshes/axial_thruster_body.stl"/>
      </geometry>
      <material name="blue">
        <color rgba="0 0 1 1"/>
      </material>
    </visual>
    <collision>
      <origin rpy="0 0 0" xyz="0 0 -0.05775515"/>
      <geometry>
        <cylinder length="0.1155103" radius="0.0432145"/>
      </geometry>
    </collision>
    <inertial>
      <origin rpy="0 0 0" xyz="0 0 -0.05775515"/>
      <mass value="0.67"/>
      <inertia ixx="0.00105776855439" ixy="0" ixz="0" iyy="0.00105776855439" iyz="0" izz="0.000625610158434"/>
    </inertial>
  </link>
  <link name="axial_propeller">
    <visual>
      <origin rpy="0 1.57079632679 0" xyz="0 0 0"/>
      <geometry>
        <mesh filename="package://humrs_robot_description/meshes/axial_propeller.stl"/>
      </geometry>
      <material name="black">
        <color rgba="0 0 0 1"/>
      </material>
    </visual>
  </link>
  <joint name="axial__PROP_JOINT" type="continuous">
    <parent link="axial__INPUT_INTERFACE"/>
    <child link="axial_propeller"/>
    <origin rpy="0 0 0" xyz="0 0 -0.068235"/>
    <axis xyz="0 0 1"/>
    <dynamics damping=".1" friction="0.2"/>
    <limit effort="7.0" velocity="20"/>
  </joint>
  <transmission name="axial__PROP_JOINT_trans">
    <type>transmission_interface/SimpleTransmission</type>
    <joint name="axial__PROP_JOINT">
      <hardwareInterface>PositionJointInterface</hardwareInterface>
    </joint>
    <actuator name="axial__PROP_JOINT_motor">
      <hardwareInterface>PositionJointInterface</hardwareInterface>
      <mechanicalReduction>1</mechanicalReduction>
    </actuator>
  </transmission>
</robot>
